Workbook

Sheet Read Me
B2: Std140_TF_Results.xlsx
B4: Example results workbook for Section 7 - Building Thermal Envelope Tests Cases 195-995, & 600FF-980FF
B6: This spreadsheet contains the Standard 140, Informative Annex B8, Section B8.1 example results.
B7: See the "Table List" and "Figure List" sheets for a listing of tables and figures and their locations.
B9: This workbook can also be used to compare new results with the example results.
B10: To add new results go to sheet "Adding Results" (2nd tab) for instructions and to enter identifying information for your program.
B11: Import your results to sheet "Your Data" (3rd tab); your results will then automatically appear in the tables and figures.
B13: To print example results or example results with new user generated results go to sheet "Title Page"
B14: (4th tab) and follow the instructions starting in cell B5.
B17: SHEET GUIDE: (see Std140_TF_Results.docx for spreadsheet navigation)
B18: "Read Me" : General directions to using this workbook.
B19: "Adding Results" : Instructions for adding new results.
... B44: "K": Spare data entry sheet

Sheet Adding Results
B6: INSTRUCTIONS FOR ADDING NEW RESULTS
B8: New result data can be imported into this workbook (sheet 'YourData', next tab) and will automatically be included in tables and charts.
B10: Import data so that Cell B66 of Std140_TF_Output.xlsx is in B66 of Sheet "YourData"
B12: Check that the first value Annual Heating Load for Case 600 lands in YourData!C70.
B14: Your data will then appear in the rightmost column of each table on sheets "Tables 1" to "Tables 7" and "Tables M1" to "Tables M3".
B16: Charts are also updated with "your data" automatically.
B18: Complete the program information block just below in the cyan highlighted cells.
B19: This information is used for legend titles for the tables and graphs. See "Comparison" setting on sheet 'Title Page'
C21: Program Name and Version (with full build detail):
C22: Tested Program V1.2.3
C23: Program Version Release Date: | G23: 43845
C24: Program Name for Tables and Charts (short): | G24: Tested Prg
C25: Results Submission Date: | G25: 43900
C26: Modeler Organization for Titles (long):
C27: Testing Organization
C28: Modeler Organization for Tables and Charts (short): | G28: Org
C30: Model / Organization Indentifier for Charts (short): | G30: =IF(OR(ISTEXT(G24),ISTEXT(G28)),IF(NOT(ISTEXT(G24)),G28,IF(NOT(ISTEXT(G28)),G24,G24&"/"&G28)),"") -> Tested Prg/Org

Sheet YourData
A3: STANDARD 140 OUTPUT FORM - RESULTS | F3: Std140_TF_Output.xlsx | H3: 43831
A4: Output Spreadsheet for Standard 140 Building Thermal Fabric Modeling Comparative Test Cases of Section 7
A6: [Note to Users: This file is reorganized since 140-2017. Red text indicates content changes to 140-2017.]
A8: INSTRUCTIONS:
A10: 1. Use specified units.
A12: 2. All solar radiation data is for sum of direct and diffuse solar radiation.
A14: 3. Output terminology is defined in Section 7.3
A16: 4. Format dates using the appropriate three-character month code,
A17: one- or two-digit day, and two-digit hour code (24 hour clock), as shown below.
A19: MONTH | C19: CODE
A21: January | C21: Jan
A22: February | C22: Feb
A23: March | C23: Mar
A24: April | C24: Apr
A25: May | C25: May
A26: June | C26: Jun
A27: July | C27: Jul
A28: August | C28: Aug
A29: September | C29: Sep
A30: October | C30: Oct
A31: November | C31: Nov
A32: December | C32: Dec
A34: For example, a peak occuring on Jan 4 during the 8th hour interval (0700-0800),
A35: shall be input as:
A37: Month | B37: Day | C37: Hour
A38: Jan | B38: 4 | C38: 8
A40: 5. Data entry is restricted to the following ranges:
B41: C61…C63: | C41: Software Name, Version, and Date of Results
B42: C70…L115: | C42: Conditioned Zone Loads (Non-Free-Float Test Cases)
B43: C130…K136: | C43: Free-Float Case Zone Temperatures
B44: C155…C171: | C44: Solar Radiation, as specified
B45: C178…K178: | C45: Sky Temperature
B46: C190…R201: | C46: Monthly Conditioned Zone Loads (Cases 600 and 900)
B47: C230…T253: | C47: Specific-Day Hourly Output: incident and transmitted solar radiation and sky temperatures
B48: C262…Z285: | C48: Specific-Day Hourly Output: zone loads (selected cases) and conditioned-zone temperatures (Cases 640 and 940)
B49: C294…H317: | C49: Specific-Day Hourly Output: free float temperatures
B50: C330…C478: | C50: Case 900FF Zone Temperature Bin Data, enter 8760 hours of zone temperature data in
C51: Sheet 'TMPBIN' (next tab), as specified in Cell E1 there. Bin data will flow to C330 - C478
C52: on this sheet (sheet 'A').
B57: USER NOTE: Paste new data in row 61 and below. | C57: Program Label in C61 flows to data labels in charts and figures. Avoid overwrite or re-enter "='Adding Results'!G24" there.
...

Sheet Title Page
A5: ASHRAE Standard 140-2023 | B5: To print example results:
A6: =IF(B21="Comparison","","Informative Annex B8, Section B8.1") -> Informative Annex B8, Section B8.1 | B6: 1. Select results type in cell B21:
B7: "Example" for Standard 140 Annex B8 Example Results
A8: =IF(B21="Comparison","Test Results Comparison","Example Results") -> Example Results | B8: "Comparison" if comparing new user results with the example results
A9: for | B9: 2. Select the following sheets:
A10: Section 7 - Building Thermal Envelope and Fabric Load Cases 195-995 & 600FF-980FF | B10: "Title Page" thru "Figure List"
B11: "Tables 1" thru "Tables M3" (all tables tabs)
B12: "Fig B8-1" thru "Fig B8-H38" (all figures tabs)
A13: =IF(B21="Comparison","Results for "&'Adding Results'!$C$22,"") | B13: 3. Print, or Save to pdf.
A14: =IF(B21="Comparison","(" & 'Adding Results'!$G$24 & ")","")
A15: =IF(B21="Comparison","vs.","") | B15: The title page, and table and chart titles are based upon the selected results type,
A16: =IF(B21="Comparison","Example Results","") | B16: and for comparison results, also include inputs from the program
B17: information block of the "Adding Results" tab.
A19: =IF(B21="Comparison","Prepared By","")
A20: =IF(B21="Comparison",IF('Adding Results'!C27="","",'Adding Results'!C27),"") | B20: Results Type (Example or Comparison)
A21: =IF(B21="Comparison","("&'Adding Results'!$G$28&")","") | B21: Example
A23: =IF(B21="Comparison","Results Developed","")
A24: =IF(B21="Comparison",TEXT('Adding Results'!$G$25,"DD-MMM-YYYY"),"")
B29: Scratch area for Table Title
B30: =IF(B21="Comparison",'Title Page'!$A$5&", "&'Title Page'!$A$8&" "&'Title Page'!$A$9&" "&'Title Page'!$A$10,'Title Page'!$A$5&", "&'Title Page'!$A$6) -> ASHRAE Standard 140-2023, Informative Annex B8, Section B8.1
B31: Scratch area for Table subtitle 1
B32: =IF('Title Page'!$B$21="Example",'Title Page'!$A$8&" "&'Title Page'!$A$9&" "&'Title Page'!$A$10, YourData!$A$46&" "&'Title Page'!$A$14 &" "& 'Title Page'!$A$15&" "&"Annex B8, Section B8.1 Example Results") -> Example Results for Section 7 - Building Thermal Envelope and Fabric Load Cases 195-995 & 600FF-980FF
B33: Scratch area for Table subtitle 2
B34: =IF('Title Page'!$B$21="Example","", "By "&'Title Page'!$A$20&" "&'Title Page'!$A$21&", "&'Title Page'!$A$24)
B36: Scratch area for chart subtitles
B37: =$B$30&" "&$B$32 & IF(B34="","", (", b" & MID($B$34,2,200))) -> ASHRAE Standard 140-2023, Informative Annex B8, Section B8.1 Example Results for Section 7 - Building Thermal Envelope and Fabric Load Cases 195-995 & 600FF-980FF

Sheet Program List
C1: =IF(ISTEXT('Title Page'!$A$5),'Title Page'!$A$5,"") -> ASHRAE Standard 140-2023
C2: Computer Programs, Program Authors, and Producers of Example Results for
C3: ='Title Page'!$A$10 -> Section 7 - Building Thermal Envelope and Fabric Load Cases 195-995 & 600FF-980FF
B5: The programs used to generate the example results for Section 7 are described in Table B11-1. Under the "Computer Program" column, the first entry in each cell is the proper program name and version number. The entries in parentheses are the abbreviations for the programs used in the tables and charts of this workbook.
B7: The second column ("Authoring Organization") indicates the national research facility, university,
B8: or industry organization with expertise in building science that wrote the simulation software.
B10: The third column ("Example Results Produced By") indicates the national research facility, university, or industry organization with expertise in building science that performed the simulations. Most of the organizations that performed simulations are members of the development team for the simulation model that they ran.
B11: See Standard 140, Annex B11 for further details.
C13: TABLE B11-1
C14: Computer Programs, Program Authors, and Producers of Example Results
B16: Computer Program (Abbrev.) | C16: Authoring Organization | D16: Example Results Produced by
B17: BSIMAC 9, Version 9.0.74 (BSIMAC) | C17: Alec Johannsen Consulting Engineers, South Africa | D17: Alec Johannsen Consulting Engineers, South Africa
B18: California Simulation Engine, Version 0.861.1 (CSE) | C18: J.R. Barnaby/C.S. Barnaby/Big Ladder Software LLC/Wrightsoft Corp., United States | D18: Big Ladder Software LLC, United States
B19: DeST 2.0, Version 20190401 (DeST) | C19: Tsinghua University, China | D19: Southeast University, China Tsinghua University, China
B20: EnergyPlus, Version 9.0.1 (EnergyPlus) | C20: U.S. Department of Energy, Building Technologies Office, United States | D20: GARD Analytics, Inc., United States
B21: ESP-r, Version 13.3 (ESP-r) | C21: University of Strathclyde, United Kingdom | D21: University of Strathclyde, United Kingdom
B22: TRNSYS, Version 18.01.0001 (TRNSYS) | C22: Transsolar Energietechnik GmbH, Germany; Thermal Energy System Specialists, United States | D22: Transsolar Energietechnik GmbH, Germany
B23: TRNSYS, Versions 17.02.0005 and 18.00.0017 (N/A) | C23: Transsolar Energietechnik GmbH, Germany; Thermal Energy System Specialists, United States | D23: Ecole Polytechnique Montréal, Canadaa,b
B24: a Ecole Polytechnique and GARD also worked on simulations for developing alternative constant interior and exterior surface
B25: coefficients, applying TRNSYS and EnergyPlus, respectively.
B26: b Also checking input files versus the Transsolar participant’s files and vice versa.
B28: Note: Results for “TestSpec-Alt” are shown in Table B8-16 and in Figures B8-6, B8-H10, and B8-H11; contents of tables and figures are further described in sheet tabs labeled "Table List" and "Figure List". “TestSpec-Alt” results are alternative values resulting from optional alternative inputs for sky temperature provided in the test specification (see Section 7.2.1.1.1.2 and Annex A1, Section A1.1.1.2).

Sheet Table List
A1: =IF('Title Page'!$B$21="Example",'Title Page'!$B$30,"ASHRAE Standard 140-2023 Section 7 - Building Thermal Envelope and Fabric Load Tests") -> ASHRAE Standard 140-2023, Informative Annex B8, Section B8.1
A2: ='Title Page'!$B$32 -> Example Results for Section 7 - Building Thermal Envelope and Fabric Load Cases 195-995 & 600FF-980FF
A3: ='Title Page'!$B$34
B5: List of Tables
B7: Table | C7: Description | D7: Sheet Tab | E7: Cell Range
B8: B8-1 | C8: Annual Heating Loads | D8: Tables 1 | E8: B7 - N57
B9: B8-2 | C9: Annual Sensible Cooling Loads | E9: B59 - N109
B10: B8-3 | C10: Annual Hourly Integrated Peak Heating Loads | D10: Tables 2 | E10: B7 - AI57
B11: B8-4 | C11: Annual Hourly Integrated Peak Sensible Cooling Loads | E11: B59 - AI109
B12: B8-5 | C12: Free-Float Temperature Output | E12: B111 - AI145
B13: B8-6 | C13: Low Mass Basic Sensitivity Tests | D13: Tables 3 | E13: B7 - N58
B14: B8-7 | C14: High Mass Basic Sensitivity Tests | E14: B61 - N112
B15: B8-8 | C15: Low Mass In-Depth (Cases 195 thru 320) Sensitivity Tests | D15: Tables 4 | E15: B7 - N76
B16: B8-9 | C16: Low Mass In-Depth (Cases 395 thru 470) Sensitivity Tests | D16: Tables 5 | E16: B7 - N64
B17: B8-10 | C17: High Mass Basic and In-Depth Sensitivity Tests | E17: B67 - N122
B18: B8-11 | C18: Annual Transmissivity Coefficient of Windows | D18: Tables 6 | E18: B7 - N16
B19: B8-12 | C19: Annual Shading Coefficient of Window Shading Devices: Overhangs & Fins | E19: B18 - N25
B20: B8-13 | C20: Case 600 Annual Incident Solar Radiation (kWh/m2) | E20: B27 - N36
B21: B8-14 | C21: Case 600 Annual Transmitted Solar Radiation – Unshaded (kWh/m2) | E21: B38 - N46
B22: B8-15 | C22: Case 600 Annual Transmitted Solar Radiation –Shaded (kWh/m2) | E22: B48 - N54
B23: B8-16 | C23: Sky Temperature Output, Case 600 | D23: Tables 7 | E23: B7 - AM15
B24: B8-M1 | C24: Monthly Heating Loads | D24: Tables M1 | E24: B7 - N36
B25: B8-M2 | C25: Monthly Sensible Cooling Loads | E25: B38 - N67
B26: B8-M3 | C26: Monthly Hourly Integrated Peak Heating Loads | D26: Tables M2 | E26: B7 - AB36
B27: B8-M4 | C27: Monthly Hourly Integrated Peak Sensible Cooling Loads | E27: B38 - AB67
B28: B8-M5 | C28: Monthly Load 600-900 Sensitivity Tests | D28: Tables M3 | E28: B7 - N68

Sheet Figure List
A1: =IF('Title Page'!$B$21="Example",'Title Page'!$B$30,"ASHRAE Standard 140-2023 Section 7 - Building Thermal Envelope and Fabric Load Tests") -> ASHRAE Standard 140-2023, Informative Annex B8, Section B8.1
A2: ='Title Page'!$B$32 -> Example Results for Section 7 - Building Thermal Envelope and Fabric Load Cases 195-995 & 600FF-980FF
A3: ='Title Page'!$B$34
B5: List of Figures
B7: Figure | C7: Title | D7: Sheet Tab
B8: B8-1 | C8: Annual Incident Solar Radiation | D8: Fig B8-1 Ann Incident Solar
B9: B8-2 | C9: Annual Transmitted Solar Radiation Unshaded | D9: Fig B8-2 Ann SolRad Unshaded
B10: B8-3 | C10: Annual Transmitted Solar Radiation Shaded | D10: Fig B8-3 Ann SolRad Shaded
B11: B8-4 | C11: Annual Transmissivity Coefficient of Windows | D11: Fig B8-4 Trans Coeff
C12: (Unshaded Transmitted)/(Incident Solar Radiation)
B13: B8-5 | C13: Annual Overhang and Fin Shading Coefficients | D13: Fig B8-5 OH&Fin Shade Coeff
C14: (1-(Shaded)/(Unshaded)) Transmitted Solar Radiation
B15: B8-6 | C15: Average, Minimum and Maximum Sky Temperature, Case 600 | D15: Fig B8-6 Sky Temp
B16: B8-7 | C16: Basic: Low Mass Annual Heating | D16: Fig B8-7 Lomass Ann Heat
B17: B8-8 | C17: Basic: Low Mass Annual Sensible Cooling | D17: Fig B8-8 Lomass Ann Cool
B18: B8-9 | C18: Basic: Low Mass Peak Heating | D18: Fig B8-9 Lomass Peak Heat
B19: B8-10 | C19: Basic: Low Mass Peak Sensible Cooling | D19: Fig B8-10 Lomass Peak Cool
B20: B8-11 | C20: Basic: High Mass Annual Heating | D20: Fig B8-11 Himass Ann Heat
B21: B8-12 | C21: Basic: High Mass Annual Sensible Cooling | D21: Fig B8-12 Himass Ann Cool
B22: B8-13 | C22: Basic: High Mass Peak Heating | D22: Fig B8-13 Himass Peak Heat
B23: B8-14 | C23: Basic: High Mass Peak Sensible Cooling | D23: Fig B8-14 Himass Peak Cool
B24: B8-15 | C24: Basic and In-Depth: South Window (Delta), | D24: Fig B8-15 Delta-S Win-Ann
C25: Annual Heating and Sensible Cooling
B26: B8-16 | C26: Basic and In-Depth: South Window (Delta), | D26: Fig B8-16 Delta-S Win-Peak
C27: Peak Heating and Sensible Cooling
B28: B8-17 | C28: Basic: Window Shading and Orientation (Delta), | D28: Fig B8-17 Delta-ShadeOrient-Load
C29: Annual Heating and Sensible Cooling
B30: B8-18 | C30: Basic: Window Shading and Orientation (Delta), | D30: Fig B8-18 Delta-ShadeOrient-Peak
C31: Peak Heating and Sensible Cooling
B32: B8-19 | C32: Basic: Thermostat Setback, Vent Cooling, and Sunspace (Delta), | D32: Fig B8-19 Delta-640650960-Load
C33: Annual Heating and Sensible Cooling
B34: B8-20 | C34: Basic: Thermostat Setback, Vent Cooling, and Sunspace (Delta), | D34: Fig B8-20 Delta-640650960-Peak
C35: Peak Heating and Sensible Cooling
B36: B8-21 | C36: Basic and In-Depth: Mass Effect (Delta), | D36: Fig B8-21 Delta-Mass Effect-Ann
C37: Annual Heating and Sensible Cooling
B38: B8-22 | C38: Basic and In-Depth: Mass Effect (Delta), | D38: Fig B8-22 Delta-Mass Effect-Pk
C39: Peak Heating and Sensible Cooling
B40: B8-23 | C40: Basic: Cases 660 to 695 and 980 to 995 Annual Heating | D40: Fig B8-23 660+ Ann Heat
B41: B8-24 | C41: Basic: Cases 660 to 695 and 980 to 995 Annual Cooling | D41: Fig B8-24 660+ Ann Cool
B42: B8-25 | C42: Basic: Cases 660 to 695 and 980 to 995 Peak Heating | D42: Fig B8-25 660+ Peak Heat
...

Sheet Tables 1
B1: ='Title Page'!$B$30 -> ASHRAE Standard 140-2023, Informative Annex B8, Section B8.1
B2: ='Title Page'!$B$32 -> Example Results for Section 7 - Building Thermal Envelope and Fabric Load Cases 195-995 & 600FF-980FF
B3: ='Title Page'!$B$34
C4: Note: The statistics in the tables below are based on the listed example results.
C5: These statistics do not have any substantial importance and are not to be interpreted as acceptance criteria.
B7: Table B8-1. Annual Heating Loads (MWh)
B8: Simulation Model: | C8: ='DATA for charts'!C6 -> BSIMAC | D8: ='DATA for charts'!D6 -> CSE | E8: ='DATA for charts'!E6 -> DeST | F8: ='DATA for charts'!F6 -> EnergyPlus | G8: ='DATA for charts'!G6 -> ESP-r | H8: ='DATA for charts'!H6 -> TRNSYS | I8: Statistics for Example Results | N8: ='DATA for charts'!$S$6 -> Tested Prg
C9: ='DATA for charts'!C7 | D9: ='DATA for charts'!D7 | E9: ='DATA for charts'!E7 | F9: ='DATA for charts'!F7 | G9: ='DATA for charts'!G7 | H9: ='DATA for charts'!H7 | I9: Min | J9: Max | K9: Mean | L9: (Max-Min)/ | N9: ='DATA for charts'!$S$7
B10: Case | L10: Mean** (%)
B11: 600 Base Case, South Windows | C11: =IF(ISNUMBER(OFFSET(INDIRECT("'"&'DATA for charts'!C$5&"'!$c70"),$R11,0)),OFFSET(INDIRECT("'"&'DATA for charts'!C$5&"'!$c70"),$R11,0),"") -> 4.05 | D11: =IF(ISNUMBER(OFFSET(INDIRECT("'"&'DATA for charts'!D$5&"'!$c70"),$R11,0)),OFFSET(INDIRECT("'"&'DATA for charts'!D$5&"'!$c70"),$R11,0),"") -> 3.992755 | E11: =IF(ISNUMBER(OFFSET(INDIRECT("'"&'DATA for charts'!E$5&"'!$c70"),$R11,0)),OFFSET(INDIRECT("'"&'DATA for charts'!E$5&"'!$c70"),$R11,0),"") -> 4.047 | F11: =IF(ISNUMBER(OFFSET(INDIRECT("'"&'DATA for charts'!F$5&"'!$c70"),$R11,0)),OFFSET(INDIRECT("'"&'DATA for charts'!F$5&"'!$c70"),$R11,0),"") -> 4.3243743 | G11: =IF(ISNUMBER(OFFSET(INDIRECT("'"&'DATA for charts'!G$5&"'!$c70"),$R11,0)),OFFSET(INDIRECT("'"&'DATA for charts'!G$5&"'!$c70"),$R11,0),"") -> 4.362 | H11: =IF(ISNUMBER(OFFSET(INDIRECT("'"&'DATA for charts'!H$5&"'!$c70"),$R11,0)),OFFSET(INDIRECT("'"&'DATA for charts'!H$5&"'!$c70"),$R11,0),"") -> 4.50355 | I11: =MIN(C11:H11) -> 3.992755 | J11: =MAX(C11:H11) -> 4.50355 | K11: =AVERAGE(C11:H11) -> 4.2132799 | L11: =ABS((J11-I11)/K11) -> 0.12123453 | N11: =IF(ISNUMBER(YourData!$C70),YourData!$C70,"") | Q11: 0 | R11: 0
B12: 610 S. Windows + Overhang | C12: =IF(ISNUMBER(OFFSET(INDIRECT("'"&'DATA for charts'!C$5&"'!$c70"),$R12,0)),OFFSET(INDIRECT("'"&'DATA for charts'!C$5&"'!$c70"),$R12,0),"") -> 4.163 | D12: =IF(ISNUMBER(OFFSET(INDIRECT("'"&'DATA for charts'!D$5&"'!$c70"),$R12,0)),OFFSET(INDIRECT("'"&'DATA for charts'!D$5&"'!$c70"),$R12,0),"") -> 4.0664235 | E12: =IF(ISNUMBER(OFFSET(INDIRECT("'"&'DATA for charts'!E$5&"'!$c70"),$R12,0)),OFFSET(INDIRECT("'"&'DATA for charts'!E$5&"'!$c70"),$R12,0),"") -> 4.144 | F12: =IF(ISNUMBER(OFFSET(INDIRECT("'"&'DATA for charts'!F$5&"'!$c70"),$R12,0)),OFFSET(INDIRECT("'"&'DATA for charts'!F$5&"'!$c70"),$R12,0),"") -> 4.3748054 | G12: =IF(ISNUMBER(OFFSET(INDIRECT("'"&'DATA for charts'!G$5&"'!$c70"),$R12,0)),OFFSET(INDIRECT("'"&'DATA for charts'!G$5&"'!$c70"),$R12,0),"") -> 4.527 | H12: =IF(ISNUMBER(OFFSET(INDIRECT("'"&'DATA for charts'!H$5&"'!$c70"),$R12,0)),OFFSET(INDIRECT("'"&'DATA for charts'!H$5&"'!$c70"),$R12,0),"") -> 4.59206 | I12: =MIN(C12:H12) -> 4.0664235 | J12: =MAX(C12:H12) -> 4.59206 | K12: =AVERAGE(C12:H12) -> 4.3112148 | L12: =ABS((J12-I12)/K12) -> 0.12192306 | N12: =IF(ISNUMBER(YourData!$C71),YourData!$C71,"") | Q12: 1 | R12: =R11+1 -> 1
B13: 620 East & West Windows | C13: =IF(ISNUMBER(OFFSET(INDIRECT("'"&'DATA for charts'!C$5&"'!$c70"),$R13,0)),OFFSET(INDIRECT("'"&'DATA for charts'!C$5&"'!$c70"),$R13,0),"") -> 4.37 | D13: =IF(ISNUMBER(OFFSET(INDIRECT("'"&'DATA for charts'!D$5&"'!$c70"),$R13,0)),OFFSET(INDIRECT("'"&'DATA for charts'!D$5&"'!$c70"),$R13,0),"") -> 4.0935981 | E13: =IF(ISNUMBER(OFFSET(INDIRECT("'"&'DATA for charts'!E$5&"'!$c70"),$R13,0)),OFFSET(INDIRECT("'"&'DATA for charts'!E$5&"'!$c70"),$R13,0),"") -> 4.297 | F13: =IF(ISNUMBER(OFFSET(INDIRECT("'"&'DATA for charts'!F$5&"'!$c70"),$R13,0)),OFFSET(INDIRECT("'"&'DATA for charts'!F$5&"'!$c70"),$R13,0),"") -> 4.4850772 | G13: =IF(ISNUMBER(OFFSET(INDIRECT("'"&'DATA for charts'!G$5&"'!$c70"),$R13,0)),OFFSET(INDIRECT("'"&'DATA for charts'!G$5&"'!$c70"),$R13,0),"") -> 4.5143 | H13: =IF(ISNUMBER(OFFSET(INDIRECT("'"&'DATA for charts'!H$5&"'!$c70"),$R13,0)),OFFSET(INDIRECT("'"&'DATA for charts'!H$5&"'!$c70"),$R13,0),"") -> 4.71898 | I13: =MIN(C13:H13) -> 4.0935981 | J13: =MAX(C13:H13) -> 4.71898 | K13: =AVERAGE(C13:H13) -> 4.4131592 | L13: =ABS((J13-I13)/K13) -> 0.14170844 | N13: =IF(ISNUMBER(YourData!$C72),YourData!$C72,"") | Q13: 2 | R13: =R12+1 -> 2
B14: 630 E&W Windows + Overhang & Fins | C14: =IF(ISNUMBER(OFFSET(INDIRECT("'"&'DATA for charts'!C$5&"'!$c70"),$R14,0)),OFFSET(INDIRECT("'"&'DATA for charts'!C$5&"'!$c70"),$R14,0),"") -> 4.923 | D14: =IF(ISNUMBER(OFFSET(INDIRECT("'"&'DATA for charts'!D$5&"'!$c70"),$R14,0)),OFFSET(INDIRECT("'"&'DATA for charts'!D$5&"'!$c70"),$R14,0),"") -> 4.3559459 | E14: =IF(ISNUMBER(OFFSET(INDIRECT("'"&'DATA for charts'!E$5&"'!$c70"),$R14,0)),OFFSET(INDIRECT("'"&'DATA for charts'!E$5&"'!$c70"),$R14,0),"") -> 4.677 | F14: =IF(ISNUMBER(OFFSET(INDIRECT("'"&'DATA for charts'!F$5&"'!$c70"),$R14,0)),OFFSET(INDIRECT("'"&'DATA for charts'!F$5&"'!$c70"),$R14,0),"") -> 4.7835485 | G14: =IF(ISNUMBER(OFFSET(INDIRECT("'"&'DATA for charts'!G$5&"'!$c70"),$R14,0)),OFFSET(INDIRECT("'"&'DATA for charts'!G$5&"'!$c70"),$R14,0),"") -> 5.0506 | H14: =IF(ISNUMBER(OFFSET(INDIRECT("'"&'DATA for charts'!H$5&"'!$c70"),$R14,0)),OFFSET(INDIRECT("'"&'DATA for charts'!H$5&"'!$c70"),$R14,0),"") -> 5.13858 | I14: =MIN(C14:H14) -> 4.3559459 | J14: =MAX(C14:H14) -> 5.13858 | K14: =AVERAGE(C14:H14) -> 4.8214457 | L14: =ABS((J14-I14)/K14) -> 0.16232353 | N14: =IF(ISNUMBER(YourData!$C73),YourData!$C73,"") | Q14: 3 | R14: =R13+1 -> 3
B15: 640 Case 600 with Htg Temp. Setback | C15: =IF(ISNUMBER(OFFSET(INDIRECT("'"&'DATA for charts'!C$5&"'!$c70"),$R15,0)),OFFSET(INDIRECT("'"&'DATA for charts'!C$5&"'!$c70"),$R15,0),"") -> 2.682 | D15: =IF(ISNUMBER(OFFSET(INDIRECT("'"&'DATA for charts'!D$5&"'!$c70"),$R15,0)),OFFSET(INDIRECT("'"&'DATA for charts'!D$5&"'!$c70"),$R15,0),"") -> 2.4032419 | E15: =IF(ISNUMBER(OFFSET(INDIRECT("'"&'DATA for charts'!E$5&"'!$c70"),$R15,0)),OFFSET(INDIRECT("'"&'DATA for charts'!E$5&"'!$c70"),$R15,0),"") -> 2.619 | F15: =IF(ISNUMBER(OFFSET(INDIRECT("'"&'DATA for charts'!F$5&"'!$c70"),$R15,0)),OFFSET(INDIRECT("'"&'DATA for charts'!F$5&"'!$c70"),$R15,0),"") -> 2.6618442 | G15: =IF(ISNUMBER(OFFSET(INDIRECT("'"&'DATA for charts'!G$5&"'!$c70"),$R15,0)),OFFSET(INDIRECT("'"&'DATA for charts'!G$5&"'!$c70"),$R15,0),"") -> 2.6544 | H15: =IF(ISNUMBER(OFFSET(INDIRECT("'"&'DATA for charts'!H$5&"'!$c70"),$R15,0)),OFFSET(INDIRECT("'"&'DATA for charts'!H$5&"'!$c70"),$R15,0),"") -> 2.65275 | I15: =MIN(C15:H15) -> 2.4032419 | J15: =MAX(C15:H15) -> 2.682 | K15: =AVERAGE(C15:H15) -> 2.612206 | L15: =ABS((J15-I15)/K15) -> 0.10671369 | N15: =IF(ISNUMBER(YourData!$C74),YourData!$C74,"") | Q15: 4 | R15: =R14+1 -> 4
B16: 650 Case 600 with Night Ventilation | C16: =IF(ISNUMBER(OFFSET(INDIRECT("'"&'DATA for charts'!C$5&"'!$c70"),$R16,0)),OFFSET(INDIRECT("'"&'DATA for charts'!C$5&"'!$c70"),$R16,0),"") -> 0 | D16: =IF(ISNUMBER(OFFSET(INDIRECT("'"&'DATA for charts'!D$5&"'!$c70"),$R16,0)),OFFSET(INDIRECT("'"&'DATA for charts'!D$5&"'!$c70"),$R16,0),"") -> 0 | E16: =IF(ISNUMBER(OFFSET(INDIRECT("'"&'DATA for charts'!E$5&"'!$c70"),$R16,0)),OFFSET(INDIRECT("'"&'DATA for charts'!E$5&"'!$c70"),$R16,0),"") -> 0 | F16: =IF(ISNUMBER(OFFSET(INDIRECT("'"&'DATA for charts'!F$5&"'!$c70"),$R16,0)),OFFSET(INDIRECT("'"&'DATA for charts'!F$5&"'!$c70"),$R16,0),"") -> 0 | G16: =IF(ISNUMBER(OFFSET(INDIRECT("'"&'DATA for charts'!G$5&"'!$c70"),$R16,0)),OFFSET(INDIRECT("'"&'DATA for charts'!G$5&"'!$c70"),$R16,0),"") -> 0 | H16: =IF(ISNUMBER(OFFSET(INDIRECT("'"&'DATA for charts'!H$5&"'!$c70"),$R16,0)),OFFSET(INDIRECT("'"&'DATA for charts'!H$5&"'!$c70"),$R16,0),"") -> 0 | I16: =MIN(C16:H16) -> 0 | J16: =MAX(C16:H16) -> 0 | K16: =AVERAGE(C16:H16) -> 0 | L16: ---- | N16: =IF(ISNUMBER(YourData!$C75),YourData!$C75,"") | Q16: 5 | R16: =R15+1 -> 5
B17: 660 Low-E Windows | C17: =IF(ISNUMBER(OFFSET(INDIRECT("'"&'DATA for charts'!C$5&"'!$c70"),$R17,0)),OFFSET(INDIRECT("'"&'DATA for charts'!C$5&"'!$c70"),$R17,0),"") -> 3.574 | D17: =IF(ISNUMBER(OFFSET(INDIRECT("'"&'DATA for charts'!D$5&"'!$c70"),$R17,0)),OFFSET(INDIRECT("'"&'DATA for charts'!D$5&"'!$c70"),$R17,0),"") -> 3.6019588 | E17: =IF(ISNUMBER(OFFSET(INDIRECT("'"&'DATA for charts'!E$5&"'!$c70"),$R17,0)),OFFSET(INDIRECT("'"&'DATA for charts'!E$5&"'!$c70"),$R17,0),"") -> 3.821 | F17: =IF(ISNUMBER(OFFSET(INDIRECT("'"&'DATA for charts'!F$5&"'!$c70"),$R17,0)),OFFSET(INDIRECT("'"&'DATA for charts'!F$5&"'!$c70"),$R17,0),"") -> 3.7067372 | G17: =IF(ISNUMBER(OFFSET(INDIRECT("'"&'DATA for charts'!G$5&"'!$c70"),$R17,0)),OFFSET(INDIRECT("'"&'DATA for charts'!G$5&"'!$c70"),$R17,0),"") -> 3.787 | H17: =IF(ISNUMBER(OFFSET(INDIRECT("'"&'DATA for charts'!H$5&"'!$c70"),$R17,0)),OFFSET(INDIRECT("'"&'DATA for charts'!H$5&"'!$c70"),$R17,0),"") -> 3.78966 | I17: =MIN(C17:H17) -> 3.574 | J17: =MAX(C17:H17) -> 3.821 | K17: =AVERAGE(C17:H17) -> 3.7133927 | L17: =ABS((J17-I17)/K17) -> 0.066515993 | N17: =IF(ISNUMBER(YourData!$C76),YourData!$C76,"") | R17: =R16+1 -> 6
B18: 670 Single-Pane Windows | C18: =IF(ISNUMBER(OFFSET(INDIRECT("'"&'DATA for charts'!C$5&"'!$c70"),$R18,0)),OFFSET(INDIRECT("'"&'DATA for charts'!C$5&"'!$c70"),$R18,0),"") -> 5.484 | D18: =IF(ISNUMBER(OFFSET(INDIRECT("'"&'DATA for charts'!D$5&"'!$c70"),$R18,0)),OFFSET(INDIRECT("'"&'DATA for charts'!D$5&"'!$c70"),$R18,0),"") -> 5.3001782 | E18: =IF(ISNUMBER(OFFSET(INDIRECT("'"&'DATA for charts'!E$5&"'!$c70"),$R18,0)),OFFSET(INDIRECT("'"&'DATA for charts'!E$5&"'!$c70"),$R18,0),"") -> 5.573 | F18: =IF(ISNUMBER(OFFSET(INDIRECT("'"&'DATA for charts'!F$5&"'!$c70"),$R18,0)),OFFSET(INDIRECT("'"&'DATA for charts'!F$5&"'!$c70"),$R18,0),"") -> 5.616125 | G18: =IF(ISNUMBER(OFFSET(INDIRECT("'"&'DATA for charts'!G$5&"'!$c70"),$R18,0)),OFFSET(INDIRECT("'"&'DATA for charts'!G$5&"'!$c70"),$R18,0),"") -> 5.975 | H18: =IF(ISNUMBER(OFFSET(INDIRECT("'"&'DATA for charts'!H$5&"'!$c70"),$R18,0)),OFFSET(INDIRECT("'"&'DATA for charts'!H$5&"'!$c70"),$R18,0),"") -> 6.13987 | I18: =MIN(C18:H18) -> 5.3001782 | J18: =MAX(C18:H18) -> 6.13987 | K18: =AVERAGE(C18:H18) -> 5.6813622 | L18: =ABS((J18-I18)/K18) -> 0.14779762 | N18: =IF(ISNUMBER(YourData!$C77),YourData!$C77,"") | R18: =R17+1 -> 7
B19: 680 Case 600 with Increased Insulation | C19: =IF(ISNUMBER(OFFSET(INDIRECT("'"&'DATA for charts'!C$5&"'!$c70"),$R19,0)),OFFSET(INDIRECT("'"&'DATA for charts'!C$5&"'!$c70"),$R19,0),"") -> 2.219 | D19: =IF(ISNUMBER(OFFSET(INDIRECT("'"&'DATA for charts'!D$5&"'!$c70"),$R19,0)),OFFSET(INDIRECT("'"&'DATA for charts'!D$5&"'!$c70"),$R19,0),"") -> 1.7861018 | E19: =IF(ISNUMBER(OFFSET(INDIRECT("'"&'DATA for charts'!E$5&"'!$c70"),$R19,0)),OFFSET(INDIRECT("'"&'DATA for charts'!E$5&"'!$c70"),$R19,0),"") -> 1.732 | F19: =IF(ISNUMBER(OFFSET(INDIRECT("'"&'DATA for charts'!F$5&"'!$c70"),$R19,0)),OFFSET(INDIRECT("'"&'DATA for charts'!F$5&"'!$c70"),$R19,0),"") -> 2.1796676 | G19: =IF(ISNUMBER(OFFSET(INDIRECT("'"&'DATA for charts'!G$5&"'!$c70"),$R19,0)),OFFSET(INDIRECT("'"&'DATA for charts'!G$5&"'!$c70"),$R19,0),"") -> 2.1321 | H19: =IF(ISNUMBER(OFFSET(INDIRECT("'"&'DATA for charts'!H$5&"'!$c70"),$R19,0)),OFFSET(INDIRECT("'"&'DATA for charts'!H$5&"'!$c70"),$R19,0),"") -> 2.28626 | I19: =MIN(C19:H19) -> 1.732 | J19: =MAX(C19:H19) -> 2.28626 | K19: =AVERAGE(C19:H19) -> 2.0558549 | L19: =ABS((J19-I19)/K19) -> 0.26960074 | N19: =IF(ISNUMBER(YourData!$C78),YourData!$C78,"") | R19: =R18+1 -> 8
B20: 685 Case 600 with "20/20" Thermostat | C20: =IF(ISNUMBER(OFFSET(INDIRECT("'"&'DATA for charts'!C$5&"'!$c70"),$R20,0)),OFFSET(INDIRECT("'"&'DATA for charts'!C$5&"'!$c70"),$R20,0),"") -> 4.532 | D20: =IF(ISNUMBER(OFFSET(INDIRECT("'"&'DATA for charts'!D$5&"'!$c70"),$R20,0)),OFFSET(INDIRECT("'"&'DATA for charts'!D$5&"'!$c70"),$R20,0),"") -> 4.5744279 | E20: =IF(ISNUMBER(OFFSET(INDIRECT("'"&'DATA for charts'!E$5&"'!$c70"),$R20,0)),OFFSET(INDIRECT("'"&'DATA for charts'!E$5&"'!$c70"),$R20,0),"") -> 4.646 | F20: =IF(ISNUMBER(OFFSET(INDIRECT("'"&'DATA for charts'!F$5&"'!$c70"),$R20,0)),OFFSET(INDIRECT("'"&'DATA for charts'!F$5&"'!$c70"),$R20,0),"") -> 4.87712 | G20: =IF(ISNUMBER(OFFSET(INDIRECT("'"&'DATA for charts'!G$5&"'!$c70"),$R20,0)),OFFSET(INDIRECT("'"&'DATA for charts'!G$5&"'!$c70"),$R20,0),"") -> 4.9035 | H20: =IF(ISNUMBER(OFFSET(INDIRECT("'"&'DATA for charts'!H$5&"'!$c70"),$R20,0)),OFFSET(INDIRECT("'"&'DATA for charts'!H$5&"'!$c70"),$R20,0),"") -> 5.04217 | I20: =MIN(C20:H20) -> 4.532 | J20: =MAX(C20:H20) -> 5.04217 | K20: =AVERAGE(C20:H20) -> 4.7625363 | L20: =ABS((J20-I20)/K20) -> 0.10712149 | N20: =IF(ISNUMBER(YourData!$C79),YourData!$C79,"") | R20: =R19+1 -> 9
B21: 695 Case 685 with Increased Insulation | C21: =IF(ISNUMBER(OFFSET(INDIRECT("'"&'DATA for charts'!C$5&"'!$c70"),$R21,0)),OFFSET(INDIRECT("'"&'DATA for charts'!C$5&"'!$c70"),$R21,0),"") -> 2.709 | D21: =IF(ISNUMBER(OFFSET(INDIRECT("'"&'DATA for charts'!D$5&"'!$c70"),$R21,0)),OFFSET(INDIRECT("'"&'DATA for charts'!D$5&"'!$c70"),$R21,0),"") -> 2.4152635 | E21: =IF(ISNUMBER(OFFSET(INDIRECT("'"&'DATA for charts'!E$5&"'!$c70"),$R21,0)),OFFSET(INDIRECT("'"&'DATA for charts'!E$5&"'!$c70"),$R21,0),"") -> 2.385 | F21: =IF(ISNUMBER(OFFSET(INDIRECT("'"&'DATA for charts'!F$5&"'!$c70"),$R21,0)),OFFSET(INDIRECT("'"&'DATA for charts'!F$5&"'!$c70"),$R21,0),"") -> 2.8018968 | G21: =IF(ISNUMBER(OFFSET(INDIRECT("'"&'DATA for charts'!G$5&"'!$c70"),$R21,0)),OFFSET(INDIRECT("'"&'DATA for charts'!G$5&"'!$c70"),$R21,0),"") -> 2.7321 | H21: =IF(ISNUMBER(OFFSET(INDIRECT("'"&'DATA for charts'!H$5&"'!$c70"),$R21,0)),OFFSET(INDIRECT("'"&'DATA for charts'!H$5&"'!$c70"),$R21,0),"") -> 2.89174 | I21: =MIN(C21:H21) -> 2.385 | J21: =MAX(C21:H21) -> 2.89174 | K21: =AVERAGE(C21:H21) -> 2.6558334 | L21: =ABS((J21-I21)/K21) -> 0.19080263 | N21: =IF(ISNUMBER(YourData!$C80),YourData!$C80,"") | R21: =R20+1 -> 10
B22: 900 South Windows | C22: =IF(ISNUMBER(OFFSET(INDIRECT("'"&'DATA for charts'!C$5&"'!$c70"),$R22,0)),OFFSET(INDIRECT("'"&'DATA for charts'!C$5&"'!$c70"),$R22,0),"") -> 1.726 | D22: =IF(ISNUMBER(OFFSET(INDIRECT("'"&'DATA for charts'!D$5&"'!$c70"),$R22,0)),OFFSET(INDIRECT("'"&'DATA for charts'!D$5&"'!$c70"),$R22,0),"") -> 1.3788913 | E22: =IF(ISNUMBER(OFFSET(INDIRECT("'"&'DATA for charts'!E$5&"'!$c70"),$R22,0)),OFFSET(INDIRECT("'"&'DATA for charts'!E$5&"'!$c70"),$R22,0),"") -> 1.591 | F22: =IF(ISNUMBER(OFFSET(INDIRECT("'"&'DATA for charts'!F$5&"'!$c70"),$R22,0)),OFFSET(INDIRECT("'"&'DATA for charts'!F$5&"'!$c70"),$R22,0),"") -> 1.6636867 | G22: =IF(ISNUMBER(OFFSET(INDIRECT("'"&'DATA for charts'!G$5&"'!$c70"),$R22,0)),OFFSET(INDIRECT("'"&'DATA for charts'!G$5&"'!$c70"),$R22,0),"") -> 1.5847 | H22: =IF(ISNUMBER(OFFSET(INDIRECT("'"&'DATA for charts'!H$5&"'!$c70"),$R22,0)),OFFSET(INDIRECT("'"&'DATA for charts'!H$5&"'!$c70"),$R22,0),"") -> 1.81403 | I22: =MIN(C22:H22) -> 1.3788913 | J22: =MAX(C22:H22) -> 1.81403 | K22: =AVERAGE(C22:H22) -> 1.6263847 | L22: =ABS((J22-I22)/K22) -> 0.26754969 | N22: =IF(ISNUMBER(YourData!$C81),YourData!$C81,"") | Q22: 6 | R22: =R21+1 -> 11
B23: 910 S. Windows + Overhang | C23: =IF(ISNUMBER(OFFSET(INDIRECT("'"&'DATA for charts'!C$5&"'!$c70"),$R23,0)),OFFSET(INDIRECT("'"&'DATA for charts'!C$5&"'!$c70"),$R23,0),"") -> 2.163 | D23: =IF(ISNUMBER(OFFSET(INDIRECT("'"&'DATA for charts'!D$5&"'!$c70"),$R23,0)),OFFSET(INDIRECT("'"&'DATA for charts'!D$5&"'!$c70"),$R23,0),"") -> 1.6476823 | E23: =IF(ISNUMBER(OFFSET(INDIRECT("'"&'DATA for charts'!E$5&"'!$c70"),$R23,0)),OFFSET(INDIRECT("'"&'DATA for charts'!E$5&"'!$c70"),$R23,0),"") -> 1.86 | F23: =IF(ISNUMBER(OFFSET(INDIRECT("'"&'DATA for charts'!F$5&"'!$c70"),$R23,0)),OFFSET(INDIRECT("'"&'DATA for charts'!F$5&"'!$c70"),$R23,0),"") -> 1.9557369 | G23: =IF(ISNUMBER(OFFSET(INDIRECT("'"&'DATA for charts'!G$5&"'!$c70"),$R23,0)),OFFSET(INDIRECT("'"&'DATA for charts'!G$5&"'!$c70"),$R23,0),"") -> 2.0672 | H23: =IF(ISNUMBER(OFFSET(INDIRECT("'"&'DATA for charts'!H$5&"'!$c70"),$R23,0)),OFFSET(INDIRECT("'"&'DATA for charts'!H$5&"'!$c70"),$R23,0),"") -> 2.13179 | I23: =MIN(C23:H23) -> 1.6476823 | J23: =MAX(C23:H23) -> 2.163 | K23: =AVERAGE(C23:H23) -> 1.9709015 | L23: =ABS((J23-I23)/K23) -> 0.26146291 | N23: =IF(ISNUMBER(YourData!$C82),YourData!$C82,"") | Q23: 7 | R23: =R22+1 -> 12
B24: 920 East & West Windows | C24: =IF(ISNUMBER(OFFSET(INDIRECT("'"&'DATA for charts'!C$5&"'!$c70"),$R24,0)),OFFSET(INDIRECT("'"&'DATA for charts'!C$5&"'!$c70"),$R24,0),"") -> 3.5 | D24: =IF(ISNUMBER(OFFSET(INDIRECT("'"&'DATA for charts'!D$5&"'!$c70"),$R24,0)),OFFSET(INDIRECT("'"&'DATA for charts'!D$5&"'!$c70"),$R24,0),"") -> 2.9560685 | E24: =IF(ISNUMBER(OFFSET(INDIRECT("'"&'DATA for charts'!E$5&"'!$c70"),$R24,0)),OFFSET(INDIRECT("'"&'DATA for charts'!E$5&"'!$c70"),$R24,0),"") -> 3.259 | F24: =IF(ISNUMBER(OFFSET(INDIRECT("'"&'DATA for charts'!F$5&"'!$c70"),$R24,0)),OFFSET(INDIRECT("'"&'DATA for charts'!F$5&"'!$c70"),$R24,0),"") -> 3.3365101 | G24: =IF(ISNUMBER(OFFSET(INDIRECT("'"&'DATA for charts'!G$5&"'!$c70"),$R24,0)),OFFSET(INDIRECT("'"&'DATA for charts'!G$5&"'!$c70"),$R24,0),"") -> 3.2997 | H24: =IF(ISNUMBER(OFFSET(INDIRECT("'"&'DATA for charts'!H$5&"'!$c70"),$R24,0)),OFFSET(INDIRECT("'"&'DATA for charts'!H$5&"'!$c70"),$R24,0),"") -> 3.6067 | I24: =MIN(C24:H24) -> 2.9560685 | J24: =MAX(C24:H24) -> 3.6067 | K24: =AVERAGE(C24:H24) -> 3.3263298 | L24: =ABS((J24-I24)/K24) -> 0.19560042 | N24: =IF(ISNUMBER(YourData!$C83),YourData!$C83,"") | Q24: 8 | R24: =R23+1 -> 13
B25: 930 E&W Windows + Overhang & Fins | C25: =IF(ISNUMBER(OFFSET(INDIRECT("'"&'DATA for charts'!C$5&"'!$c70"),$R25,0)),OFFSET(INDIRECT("'"&'DATA for charts'!C$5&"'!$c70"),$R25,0),"") -> 4.27 | D25: =IF(ISNUMBER(OFFSET(INDIRECT("'"&'DATA for charts'!D$5&"'!$c70"),$R25,0)),OFFSET(INDIRECT("'"&'DATA for charts'!D$5&"'!$c70"),$R25,0),"") -> 3.5236475 | E25: =IF(ISNUMBER(OFFSET(INDIRECT("'"&'DATA for charts'!E$5&"'!$c70"),$R25,0)),OFFSET(INDIRECT("'"&'DATA for charts'!E$5&"'!$c70"),$R25,0),"") -> 3.933 | F25: =IF(ISNUMBER(OFFSET(INDIRECT("'"&'DATA for charts'!F$5&"'!$c70"),$R25,0)),OFFSET(INDIRECT("'"&'DATA for charts'!F$5&"'!$c70"),$R25,0),"") -> 3.9938127 | G25: =IF(ISNUMBER(OFFSET(INDIRECT("'"&'DATA for charts'!G$5&"'!$c70"),$R25,0)),OFFSET(INDIRECT("'"&'DATA for charts'!G$5&"'!$c70"),$R25,0),"") -> 4.2776 | H25: =IF(ISNUMBER(OFFSET(INDIRECT("'"&'DATA for charts'!H$5&"'!$c70"),$R25,0)),OFFSET(INDIRECT("'"&'DATA for charts'!H$5&"'!$c70"),$R25,0),"") -> 4.3841 | I25: =MIN(C25:H25) -> 3.5236475 | J25: =MAX(C25:H25) -> 4.3841 | K25: =AVERAGE(C25:H25) -> 4.0636934 | L25: =ABS((J25-I25)/K25) -> 0.2117415 | N25: =IF(ISNUMBER(YourData!$C84),YourData!$C84,"") | Q25: 9 | R25: =R24+1 -> 14
B26: 940 Case 900 with Htg Temp. Setback | C26: =IF(ISNUMBER(OFFSET(INDIRECT("'"&'DATA for charts'!C$5&"'!$c70"),$R26,0)),OFFSET(INDIRECT("'"&'DATA for charts'!C$5&"'!$c70"),$R26,0),"") -> 1.389 | D26: =IF(ISNUMBER(OFFSET(INDIRECT("'"&'DATA for charts'!D$5&"'!$c70"),$R26,0)),OFFSET(INDIRECT("'"&'DATA for charts'!D$5&"'!$c70"),$R26,0),"") -> 0.86323595 | E26: =IF(ISNUMBER(OFFSET(INDIRECT("'"&'DATA for charts'!E$5&"'!$c70"),$R26,0)),OFFSET(INDIRECT("'"&'DATA for charts'!E$5&"'!$c70"),$R26,0),"") -> 1.149 | F26: =IF(ISNUMBER(OFFSET(INDIRECT("'"&'DATA for charts'!F$5&"'!$c70"),$R26,0)),OFFSET(INDIRECT("'"&'DATA for charts'!F$5&"'!$c70"),$R26,0),"") -> 1.0673847 | G26: =IF(ISNUMBER(OFFSET(INDIRECT("'"&'DATA for charts'!G$5&"'!$c70"),$R26,0)),OFFSET(INDIRECT("'"&'DATA for charts'!G$5&"'!$c70"),$R26,0),"") -> 1.0147 | H26: =IF(ISNUMBER(OFFSET(INDIRECT("'"&'DATA for charts'!H$5&"'!$c70"),$R26,0)),OFFSET(INDIRECT("'"&'DATA for charts'!H$5&"'!$c70"),$R26,0),"") -> 1.16913 | I26: =MIN(C26:H26) -> 0.86323595 | J26: =MAX(C26:H26) -> 1.389 | K26: =AVERAGE(C26:H26) -> 1.1087418 | L26: =ABS((J26-I26)/K26) -> 0.47419883 | N26: =IF(ISNUMBER(YourData!$C85),YourData!$C85,"") | Q26: 10 | R26: =R25+1 -> 15
B27: 950 Case 900 with Night Ventilation | C27: =IF(ISNUMBER(OFFSET(INDIRECT("'"&'DATA for charts'!C$5&"'!$c70"),$R27,0)),OFFSET(INDIRECT("'"&'DATA for charts'!C$5&"'!$c70"),$R27,0),"") -> 0 | D27: =IF(ISNUMBER(OFFSET(INDIRECT("'"&'DATA for charts'!D$5&"'!$c70"),$R27,0)),OFFSET(INDIRECT("'"&'DATA for charts'!D$5&"'!$c70"),$R27,0),"") -> 0 | E27: =IF(ISNUMBER(OFFSET(INDIRECT("'"&'DATA for charts'!E$5&"'!$c70"),$R27,0)),OFFSET(INDIRECT("'"&'DATA for charts'!E$5&"'!$c70"),$R27,0),"") -> 0 | F27: =IF(ISNUMBER(OFFSET(INDIRECT("'"&'DATA for charts'!F$5&"'!$c70"),$R27,0)),OFFSET(INDIRECT("'"&'DATA for charts'!F$5&"'!$c70"),$R27,0),"") -> 0 | G27: =IF(ISNUMBER(OFFSET(INDIRECT("'"&'DATA for charts'!G$5&"'!$c70"),$R27,0)),OFFSET(INDIRECT("'"&'DATA for charts'!G$5&"'!$c70"),$R27,0),"") -> 0 | H27: =IF(ISNUMBER(OFFSET(INDIRECT("'"&'DATA for charts'!H$5&"'!$c70"),$R27,0)),OFFSET(INDIRECT("'"&'DATA for charts'!H$5&"'!$c70"),$R27,0),"") -> 0 | I27: =MIN(C27:H27) -> 0 | J27: =MAX(C27:H27) -> 0 | K27: =AVERAGE(C27:H27) -> 0 | L27: ---- | N27: =IF(ISNUMBER(YourData!$C86),YourData!$C86,"") | Q27: 11 | R27: =R26+1 -> 16
B28: 960 Sunspace | C28: =IF(ISNUMBER(OFFSET(INDIRECT("'"&'DATA for charts'!C$5&"'!$c70"),$R28,0)),OFFSET(INDIRECT("'"&'DATA for charts'!C$5&"'!$c70"),$R28,0),"") | D28: =IF(ISNUMBER(OFFSET(INDIRECT("'"&'DATA for charts'!D$5&"'!$c70"),$R28,0)),OFFSET(INDIRECT("'"&'DATA for charts'!D$5&"'!$c70"),$R28,0),"") -> 2.522072 | E28: =IF(ISNUMBER(OFFSET(INDIRECT("'"&'DATA for charts'!E$5&"'!$c70"),$R28,0)),OFFSET(INDIRECT("'"&'DATA for charts'!E$5&"'!$c70"),$R28,0),"") -> 2.771 | F28: =IF(ISNUMBER(OFFSET(INDIRECT("'"&'DATA for charts'!F$5&"'!$c70"),$R28,0)),OFFSET(INDIRECT("'"&'DATA for charts'!F$5&"'!$c70"),$R28,0),"") -> 2.6890439 | G28: =IF(ISNUMBER(OFFSET(INDIRECT("'"&'DATA for charts'!G$5&"'!$c70"),$R28,0)),OFFSET(INDIRECT("'"&'DATA for charts'!G$5&"'!$c70"),$R28,0),"") -> 2.6239 | H28: =IF(ISNUMBER(OFFSET(INDIRECT("'"&'DATA for charts'!H$5&"'!$c70"),$R28,0)),OFFSET(INDIRECT("'"&'DATA for charts'!H$5&"'!$c70"),$R28,0),"") -> 2.85954 | I28: =MIN(C28:H28) -> 2.522072 | J28: =MAX(C28:H28) -> 2.85954 | K28: =AVERAGE(C28:H28) -> 2.6931112 | L28: =ABS((J28-I28)/K28) -> 0.12530786 | N28: =IF(ISNUMBER(YourData!$C87),YourData!$C87,"") | Q28: 12 | R28: =R27+1 -> 17
B29: 980 Case 900 with Increased Insulation | C29: =IF(ISNUMBER(OFFSET(INDIRECT("'"&'DATA for charts'!C$5&"'!$c70"),$R29,0)),OFFSET(INDIRECT("'"&'DATA for charts'!C$5&"'!$c70"),$R29,0),"") -> 0.72 | D29: =IF(ISNUMBER(OFFSET(INDIRECT("'"&'DATA for charts'!D$5&"'!$c70"),$R29,0)),OFFSET(INDIRECT("'"&'DATA for charts'!D$5&"'!$c70"),$R29,0),"") -> 0.2457661 | E29: =IF(ISNUMBER(OFFSET(INDIRECT("'"&'DATA for charts'!E$5&"'!$c70"),$R29,0)),OFFSET(INDIRECT("'"&'DATA for charts'!E$5&"'!$c70"),$R29,0),"") -> 0.266 | F29: =IF(ISNUMBER(OFFSET(INDIRECT("'"&'DATA for charts'!F$5&"'!$c70"),$R29,0)),OFFSET(INDIRECT("'"&'DATA for charts'!F$5&"'!$c70"),$R29,0),"") -> 0.4109414 | G29: =IF(ISNUMBER(OFFSET(INDIRECT("'"&'DATA for charts'!G$5&"'!$c70"),$R29,0)),OFFSET(INDIRECT("'"&'DATA for charts'!G$5&"'!$c70"),$R29,0),"") -> 0.3511 | H29: =IF(ISNUMBER(OFFSET(INDIRECT("'"&'DATA for charts'!H$5&"'!$c70"),$R29,0)),OFFSET(INDIRECT("'"&'DATA for charts'!H$5&"'!$c70"),$R29,0),"") -> 0.450471 | I29: =MIN(C29:H29) -> 0.2457661 | J29: =MAX(C29:H29) -> 0.72 | K29: =AVERAGE(C29:H29) -> 0.40737975 | L29: =ABS((J29-I29)/K29) -> 1.1641077 | N29: =IF(ISNUMBER(YourData!$C88),YourData!$C88,"") | R29: =R28+1 -> 18
B30: 985 Case 900 with "20/20" Thermostat | C30: =IF(ISNUMBER(OFFSET(INDIRECT("'"&'DATA for charts'!C$5&"'!$c70"),$R30,0)),OFFSET(INDIRECT("'"&'DATA for charts'!C$5&"'!$c70"),$R30,0),"") -> 2.801 | D30: =IF(ISNUMBER(OFFSET(INDIRECT("'"&'DATA for charts'!D$5&"'!$c70"),$R30,0)),OFFSET(INDIRECT("'"&'DATA for charts'!D$5&"'!$c70"),$R30,0),"") -> 2.1202101 | E30: =IF(ISNUMBER(OFFSET(INDIRECT("'"&'DATA for charts'!E$5&"'!$c70"),$R30,0)),OFFSET(INDIRECT("'"&'DATA for charts'!E$5&"'!$c70"),$R30,0),"") -> 2.279 | F30: =IF(ISNUMBER(OFFSET(INDIRECT("'"&'DATA for charts'!F$5&"'!$c70"),$R30,0)),OFFSET(INDIRECT("'"&'DATA for charts'!F$5&"'!$c70"),$R30,0),"") -> 2.3693191 | G30: =IF(ISNUMBER(OFFSET(INDIRECT("'"&'DATA for charts'!G$5&"'!$c70"),$R30,0)),OFFSET(INDIRECT("'"&'DATA for charts'!G$5&"'!$c70"),$R30,0),"") -> 2.2833 | H30: =IF(ISNUMBER(OFFSET(INDIRECT("'"&'DATA for charts'!H$5&"'!$c70"),$R30,0)),OFFSET(INDIRECT("'"&'DATA for charts'!H$5&"'!$c70"),$R30,0),"") -> 2.53641 | I30: =MIN(C30:H30) -> 2.1202101 | J30: =MAX(C30:H30) -> 2.801 | K30: =AVERAGE(C30:H30) -> 2.3982065 | L30: =ABS((J30-I30)/K30) -> 0.28387458 | N30: =IF(ISNUMBER(YourData!$C89),YourData!$C89,"") | R30: =R29+1 -> 19
B31: 995 Case 985 with Increased Insulation | C31: =IF(ISNUMBER(OFFSET(INDIRECT("'"&'DATA for charts'!C$5&"'!$c70"),$R31,0)),OFFSET(INDIRECT("'"&'DATA for charts'!C$5&"'!$c70"),$R31,0),"") -> 1.33 | D31: =IF(ISNUMBER(OFFSET(INDIRECT("'"&'DATA for charts'!D$5&"'!$c70"),$R31,0)),OFFSET(INDIRECT("'"&'DATA for charts'!D$5&"'!$c70"),$R31,0),"") -> 0.75518159 | E31: =IF(ISNUMBER(OFFSET(INDIRECT("'"&'DATA for charts'!E$5&"'!$c70"),$R31,0)),OFFSET(INDIRECT("'"&'DATA for charts'!E$5&"'!$c70"),$R31,0),"") -> 0.77 | F31: =IF(ISNUMBER(OFFSET(INDIRECT("'"&'DATA for charts'!F$5&"'!$c70"),$R31,0)),OFFSET(INDIRECT("'"&'DATA for charts'!F$5&"'!$c70"),$R31,0),"") -> 1.0064884 | G31: =IF(ISNUMBER(OFFSET(INDIRECT("'"&'DATA for charts'!G$5&"'!$c70"),$R31,0)),OFFSET(INDIRECT("'"&'DATA for charts'!G$5&"'!$c70"),$R31,0),"") -> 0.9048 | H31: =IF(ISNUMBER(OFFSET(INDIRECT("'"&'DATA for charts'!H$5&"'!$c70"),$R31,0)),OFFSET(INDIRECT("'"&'DATA for charts'!H$5&"'!$c70"),$R31,0),"") -> 1.07704 | I31: =MIN(C31:H31) -> 0.75518159 | J31: =MAX(C31:H31) -> 1.33 | K31: =AVERAGE(C31:H31) -> 0.97391833 | L31: =ABS((J31-I31)/K31) -> 0.59021213 | N31: =IF(ISNUMBER(YourData!$C90),YourData!$C90,"") | R31: =R30+1 -> 20
B32: 195 Solid Conduction | C32: =IF(ISNUMBER(OFFSET(INDIRECT("'"&'DATA for charts'!C$5&"'!$c70"),$R32,0)),OFFSET(INDIRECT("'"&'DATA for charts'!C$5&"'!$c70"),$R32,0),"") -> 4.217 | D32: =IF(ISNUMBER(OFFSET(INDIRECT("'"&'DATA for charts'!D$5&"'!$c70"),$R32,0)),OFFSET(INDIRECT("'"&'DATA for charts'!D$5&"'!$c70"),$R32,0),"") -> 3.9900793 | E32: =IF(ISNUMBER(OFFSET(INDIRECT("'"&'DATA for charts'!E$5&"'!$c70"),$R32,0)),OFFSET(INDIRECT("'"&'DATA for charts'!E$5&"'!$c70"),$R32,0),"") -> 4.157 | F32: =IF(ISNUMBER(OFFSET(INDIRECT("'"&'DATA for charts'!F$5&"'!$c70"),$R32,0)),OFFSET(INDIRECT("'"&'DATA for charts'!F$5&"'!$c70"),$R32,0),"") -> 4.0696082 | G32: =IF(ISNUMBER(OFFSET(INDIRECT("'"&'DATA for charts'!G$5&"'!$c70"),$R32,0)),OFFSET(INDIRECT("'"&'DATA for charts'!G$5&"'!$c70"),$R32,0),"") -> 3.9509 | H32: =IF(ISNUMBER(OFFSET(INDIRECT("'"&'DATA for charts'!H$5&"'!$c70"),$R32,0)),OFFSET(INDIRECT("'"&'DATA for charts'!H$5&"'!$c70"),$R32,0),"") -> 4.09394 | I32: =MIN(C32:H32) -> 3.9509 | J32: =MAX(C32:H32) -> 4.217 | K32: =AVERAGE(C32:H32) -> 4.0797546 | L32: =ABS((J32-I32)/K32) -> 0.065224512 | N32: =IF(ISNUMBER(YourData!$C91),YourData!$C91,"") | Q32: 13 | R32: =R31+1 -> 21
B33: 200 Surface Convection (Int & Ext IR="off") | C33: =IF(ISNUMBER(OFFSET(INDIRECT("'"&'DATA for charts'!C$5&"'!$c70"),$R33,0)),OFFSET(INDIRECT("'"&'DATA for charts'!C$5&"'!$c70"),$R33,0),"") -> 5.041 | D33: =IF(ISNUMBER(OFFSET(INDIRECT("'"&'DATA for charts'!D$5&"'!$c70"),$R33,0)),OFFSET(INDIRECT("'"&'DATA for charts'!D$5&"'!$c70"),$R33,0),"") -> 4.8134514 | E33: =IF(ISNUMBER(OFFSET(INDIRECT("'"&'DATA for charts'!E$5&"'!$c70"),$R33,0)),OFFSET(INDIRECT("'"&'DATA for charts'!E$5&"'!$c70"),$R33,0),"") -> 5.226 | F33: =IF(ISNUMBER(OFFSET(INDIRECT("'"&'DATA for charts'!F$5&"'!$c70"),$R33,0)),OFFSET(INDIRECT("'"&'DATA for charts'!F$5&"'!$c70"),$R33,0),"") -> 5.1053835 | G33: =IF(ISNUMBER(OFFSET(INDIRECT("'"&'DATA for charts'!G$5&"'!$c70"),$R33,0)),OFFSET(INDIRECT("'"&'DATA for charts'!G$5&"'!$c70"),$R33,0),"") -> 4.9204 | H33: =IF(ISNUMBER(OFFSET(INDIRECT("'"&'DATA for charts'!H$5&"'!$c70"),$R33,0)),OFFSET(INDIRECT("'"&'DATA for charts'!H$5&"'!$c70"),$R33,0),"") -> 5.14288 | I33: =MIN(C33:H33) -> 4.8134514 | J33: =MAX(C33:H33) -> 5.226 | K33: =AVERAGE(C33:H33) -> 5.0415191 | L33: =ABS((J33-I33)/K33) -> 0.081830225 | N33: =IF(ISNUMBER(YourData!$C92),YourData!$C92,"") | Q33: 14 | R33: =R32+1 -> 22
B34: 210 Infrared Radiation (Int IR="off", Ext IR="on") | C34: =IF(ISNUMBER(OFFSET(INDIRECT("'"&'DATA for charts'!C$5&"'!$c70"),$R34,0)),OFFSET(INDIRECT("'"&'DATA for charts'!C$5&"'!$c70"),$R34,0),"") -> 5.627 | D34: =IF(ISNUMBER(OFFSET(INDIRECT("'"&'DATA for charts'!D$5&"'!$c70"),$R34,0)),OFFSET(INDIRECT("'"&'DATA for charts'!D$5&"'!$c70"),$R34,0),"") -> 5.9663174 | E34: =IF(ISNUMBER(OFFSET(INDIRECT("'"&'DATA for charts'!E$5&"'!$c70"),$R34,0)),OFFSET(INDIRECT("'"&'DATA for charts'!E$5&"'!$c70"),$R34,0),"") -> 6.531 | F34: =IF(ISNUMBER(OFFSET(INDIRECT("'"&'DATA for charts'!F$5&"'!$c70"),$R34,0)),OFFSET(INDIRECT("'"&'DATA for charts'!F$5&"'!$c70"),$R34,0),"") -> 6.046563 | G34: =IF(ISNUMBER(OFFSET(INDIRECT("'"&'DATA for charts'!G$5&"'!$c70"),$R34,0)),OFFSET(INDIRECT("'"&'DATA for charts'!G$5&"'!$c70"),$R34,0),"") -> 6.3171 | H34: =IF(ISNUMBER(OFFSET(INDIRECT("'"&'DATA for charts'!H$5&"'!$c70"),$R34,0)),OFFSET(INDIRECT("'"&'DATA for charts'!H$5&"'!$c70"),$R34,0),"") -> 6.42949 | I34: =MIN(C34:H34) -> 5.627 | J34: =MAX(C34:H34) -> 6.531 | K34: =AVERAGE(C34:H34) -> 6.1529117 | L34: =ABS((J34-I34)/K34) -> 0.14692231 | N34: =IF(ISNUMBER(YourData!$C93),YourData!$C93,"") | Q34: 15 | R34: =R33+1 -> 23
B35: 215 Infrared Radiation (Int IR="on", Ext IR="off") | C35: =IF(ISNUMBER(OFFSET(INDIRECT("'"&'DATA for charts'!C$5&"'!$c70"),$R35,0)),OFFSET(INDIRECT("'"&'DATA for charts'!C$5&"'!$c70"),$R35,0),"") -> 5.652 | D35: =IF(ISNUMBER(OFFSET(INDIRECT("'"&'DATA for charts'!D$5&"'!$c70"),$R35,0)),OFFSET(INDIRECT("'"&'DATA for charts'!D$5&"'!$c70"),$R35,0),"") -> 5.3066163 | E35: =IF(ISNUMBER(OFFSET(INDIRECT("'"&'DATA for charts'!E$5&"'!$c70"),$R35,0)),OFFSET(INDIRECT("'"&'DATA for charts'!E$5&"'!$c70"),$R35,0),"") -> 5.697 | F35: =IF(ISNUMBER(OFFSET(INDIRECT("'"&'DATA for charts'!F$5&"'!$c70"),$R35,0)),OFFSET(INDIRECT("'"&'DATA for charts'!F$5&"'!$c70"),$R35,0),"") -> 5.4054193 | G35: =IF(ISNUMBER(OFFSET(INDIRECT("'"&'DATA for charts'!G$5&"'!$c70"),$R35,0)),OFFSET(INDIRECT("'"&'DATA for charts'!G$5&"'!$c70"),$R35,0),"") -> 5.1811 | H35: =IF(ISNUMBER(OFFSET(INDIRECT("'"&'DATA for charts'!H$5&"'!$c70"),$R35,0)),OFFSET(INDIRECT("'"&'DATA for charts'!H$5&"'!$c70"),$R35,0),"") -> 5.44339 | I35: =MIN(C35:H35) -> 5.1811 | J35: =MAX(C35:H35) -> 5.697 | K35: =AVERAGE(C35:H35) -> 5.4475876 | L35: =ABS((J35-I35)/K35) -> 0.09470247 | N35: =IF(ISNUMBER(YourData!$C94),YourData!$C94,"") | Q35: 16 | R35: =R34+1 -> 24
B36: 220 In-Depth Base Case | C36: =IF(ISNUMBER(OFFSET(INDIRECT("'"&'DATA for charts'!C$5&"'!$c70"),$R36,0)),OFFSET(INDIRECT("'"&'DATA for charts'!C$5&"'!$c70"),$R36,0),"") -> 6.377 | D36: =IF(ISNUMBER(OFFSET(INDIRECT("'"&'DATA for charts'!D$5&"'!$c70"),$R36,0)),OFFSET(INDIRECT("'"&'DATA for charts'!D$5&"'!$c70"),$R36,0),"") -> 6.666344 | E36: =IF(ISNUMBER(OFFSET(INDIRECT("'"&'DATA for charts'!E$5&"'!$c70"),$R36,0)),OFFSET(INDIRECT("'"&'DATA for charts'!E$5&"'!$c70"),$R36,0),"") -> 7.178 | F36: =IF(ISNUMBER(OFFSET(INDIRECT("'"&'DATA for charts'!F$5&"'!$c70"),$R36,0)),OFFSET(INDIRECT("'"&'DATA for charts'!F$5&"'!$c70"),$R36,0),"") -> 6.4551361 | G36: =IF(ISNUMBER(OFFSET(INDIRECT("'"&'DATA for charts'!G$5&"'!$c70"),$R36,0)),OFFSET(INDIRECT("'"&'DATA for charts'!G$5&"'!$c70"),$R36,0),"") -> 6.7257 | H36: =IF(ISNUMBER(OFFSET(INDIRECT("'"&'DATA for charts'!H$5&"'!$c70"),$R36,0)),OFFSET(INDIRECT("'"&'DATA for charts'!H$5&"'!$c70"),$R36,0),"") -> 6.86783 | I36: =MIN(C36:H36) -> 6.377 | J36: =MAX(C36:H36) -> 7.178 | K36: =AVERAGE(C36:H36) -> 6.7116683 | L36: =ABS((J36-I36)/K36) -> 0.1193444 | N36: =IF(ISNUMBER(YourData!$C95),YourData!$C95,"") | Q36: 17 | R36: =R35+1 -> 25
B37: 230 Infiltration | C37: =IF(ISNUMBER(OFFSET(INDIRECT("'"&'DATA for charts'!C$5&"'!$c70"),$R37,0)),OFFSET(INDIRECT("'"&'DATA for charts'!C$5&"'!$c70"),$R37,0),"") -> 9.851 | D37: =IF(ISNUMBER(OFFSET(INDIRECT("'"&'DATA for charts'!D$5&"'!$c70"),$R37,0)),OFFSET(INDIRECT("'"&'DATA for charts'!D$5&"'!$c70"),$R37,0),"") -> 9.8123585 | E37: =IF(ISNUMBER(OFFSET(INDIRECT("'"&'DATA for charts'!E$5&"'!$c70"),$R37,0)),OFFSET(INDIRECT("'"&'DATA for charts'!E$5&"'!$c70"),$R37,0),"") -> 10.417 | F37: =IF(ISNUMBER(OFFSET(INDIRECT("'"&'DATA for charts'!F$5&"'!$c70"),$R37,0)),OFFSET(INDIRECT("'"&'DATA for charts'!F$5&"'!$c70"),$R37,0),"") -> 9.9298576 | G37: =IF(ISNUMBER(OFFSET(INDIRECT("'"&'DATA for charts'!G$5&"'!$c70"),$R37,0)),OFFSET(INDIRECT("'"&'DATA for charts'!G$5&"'!$c70"),$R37,0),"") -> 9.9385 | H37: =IF(ISNUMBER(OFFSET(INDIRECT("'"&'DATA for charts'!H$5&"'!$c70"),$R37,0)),OFFSET(INDIRECT("'"&'DATA for charts'!H$5&"'!$c70"),$R37,0),"") -> 10.2343 | I37: =MIN(C37:H37) -> 9.8123585 | J37: =MAX(C37:H37) -> 10.417 | K37: =AVERAGE(C37:H37) -> 10.030503 | L37: =ABS((J37-I37)/K37) -> 0.060280282 | N37: =IF(ISNUMBER(YourData!$C96),YourData!$C96,"") | Q37: 18 | R37: =R36+1 -> 26
B38: 240 Internal Gains | C38: =IF(ISNUMBER(OFFSET(INDIRECT("'"&'DATA for charts'!C$5&"'!$c70"),$R38,0)),OFFSET(INDIRECT("'"&'DATA for charts'!C$5&"'!$c70"),$R38,0),"") -> 5.116 | D38: =IF(ISNUMBER(OFFSET(INDIRECT("'"&'DATA for charts'!D$5&"'!$c70"),$R38,0)),OFFSET(INDIRECT("'"&'DATA for charts'!D$5&"'!$c70"),$R38,0),"") -> 5.4426273 | E38: =IF(ISNUMBER(OFFSET(INDIRECT("'"&'DATA for charts'!E$5&"'!$c70"),$R38,0)),OFFSET(INDIRECT("'"&'DATA for charts'!E$5&"'!$c70"),$R38,0),"") -> 5.944 | F38: =IF(ISNUMBER(OFFSET(INDIRECT("'"&'DATA for charts'!F$5&"'!$c70"),$R38,0)),OFFSET(INDIRECT("'"&'DATA for charts'!F$5&"'!$c70"),$R38,0),"") -> 5.2793766 | G38: =IF(ISNUMBER(OFFSET(INDIRECT("'"&'DATA for charts'!G$5&"'!$c70"),$R38,0)),OFFSET(INDIRECT("'"&'DATA for charts'!G$5&"'!$c70"),$R38,0),"") -> 5.5393 | H38: =IF(ISNUMBER(OFFSET(INDIRECT("'"&'DATA for charts'!H$5&"'!$c70"),$R38,0)),OFFSET(INDIRECT("'"&'DATA for charts'!H$5&"'!$c70"),$R38,0),"") -> 5.6572 | I38: =MIN(C38:H38) -> 5.116 | J38: =MAX(C38:H38) -> 5.944 | K38: =AVERAGE(C38:H38) -> 5.4964173 | L38: =ABS((J38-I38)/K38) -> 0.15064358 | N38: =IF(ISNUMBER(YourData!$C97),YourData!$C97,"") | Q38: 19 | R38: =R37+1 -> 27
B39: 250 Exterior Shortwave Absorptance | C39: =IF(ISNUMBER(OFFSET(INDIRECT("'"&'DATA for charts'!C$5&"'!$c70"),$R39,0)),OFFSET(INDIRECT("'"&'DATA for charts'!C$5&"'!$c70"),$R39,0),"") -> 4.733 | D39: =IF(ISNUMBER(OFFSET(INDIRECT("'"&'DATA for charts'!D$5&"'!$c70"),$R39,0)),OFFSET(INDIRECT("'"&'DATA for charts'!D$5&"'!$c70"),$R39,0),"") -> 5.0438461 | E39: =IF(ISNUMBER(OFFSET(INDIRECT("'"&'DATA for charts'!E$5&"'!$c70"),$R39,0)),OFFSET(INDIRECT("'"&'DATA for charts'!E$5&"'!$c70"),$R39,0),"") -> 5.373 | F39: =IF(ISNUMBER(OFFSET(INDIRECT("'"&'DATA for charts'!F$5&"'!$c70"),$R39,0)),OFFSET(INDIRECT("'"&'DATA for charts'!F$5&"'!$c70"),$R39,0),"") -> 4.899115 | G39: =IF(ISNUMBER(OFFSET(INDIRECT("'"&'DATA for charts'!G$5&"'!$c70"),$R39,0)),OFFSET(INDIRECT("'"&'DATA for charts'!G$5&"'!$c70"),$R39,0),"") -> 4.935 | H39: =IF(ISNUMBER(OFFSET(INDIRECT("'"&'DATA for charts'!H$5&"'!$c70"),$R39,0)),OFFSET(INDIRECT("'"&'DATA for charts'!H$5&"'!$c70"),$R39,0),"") -> 5.10474 | I39: =MIN(C39:H39) -> 4.733 | J39: =MAX(C39:H39) -> 5.373 | K39: =AVERAGE(C39:H39) -> 5.0147835 | L39: =ABS((J39-I39)/K39) -> 0.12762266 | N39: =IF(ISNUMBER(YourData!$C98),YourData!$C98,"") | Q39: 20 | R39: =R38+1 -> 28
B40: 270 South Solar Windows | C40: =IF(ISNUMBER(OFFSET(INDIRECT("'"&'DATA for charts'!C$5&"'!$c70"),$R40,0)),OFFSET(INDIRECT("'"&'DATA for charts'!C$5&"'!$c70"),$R40,0),"") | D40: =IF(ISNUMBER(OFFSET(INDIRECT("'"&'DATA for charts'!D$5&"'!$c70"),$R40,0)),OFFSET(INDIRECT("'"&'DATA for charts'!D$5&"'!$c70"),$R40,0),"") -> 4.3464711 | E40: =IF(ISNUMBER(OFFSET(INDIRECT("'"&'DATA for charts'!E$5&"'!$c70"),$R40,0)),OFFSET(INDIRECT("'"&'DATA for charts'!E$5&"'!$c70"),$R40,0),"") -> 4.273 | F40: =IF(ISNUMBER(OFFSET(INDIRECT("'"&'DATA for charts'!F$5&"'!$c70"),$R40,0)),OFFSET(INDIRECT("'"&'DATA for charts'!F$5&"'!$c70"),$R40,0),"") -> 4.3853513 | G40: =IF(ISNUMBER(OFFSET(INDIRECT("'"&'DATA for charts'!G$5&"'!$c70"),$R40,0)),OFFSET(INDIRECT("'"&'DATA for charts'!G$5&"'!$c70"),$R40,0),"") -> 4.5764 | H40: =IF(ISNUMBER(OFFSET(INDIRECT("'"&'DATA for charts'!H$5&"'!$c70"),$R40,0)),OFFSET(INDIRECT("'"&'DATA for charts'!H$5&"'!$c70"),$R40,0),"") -> 4.63116 | I40: =MIN(C40:H40) -> 4.273 | J40: =MAX(C40:H40) -> 4.63116 | K40: =AVERAGE(C40:H40) -> 4.4424765 | L40: =ABS((J40-I40)/K40) -> 0.080621699 | N40: =IF(ISNUMBER(YourData!$C99),YourData!$C99,"") | Q40: 21 | R40: =R39+1 -> 29
B41: 280 Cavity Albedo | C41: =IF(ISNUMBER(OFFSET(INDIRECT("'"&'DATA for charts'!C$5&"'!$c70"),$R41,0)),OFFSET(INDIRECT("'"&'DATA for charts'!C$5&"'!$c70"),$R41,0),"") | D41: =IF(ISNUMBER(OFFSET(INDIRECT("'"&'DATA for charts'!D$5&"'!$c70"),$R41,0)),OFFSET(INDIRECT("'"&'DATA for charts'!D$5&"'!$c70"),$R41,0),"") -> 4.5249314 | E41: =IF(ISNUMBER(OFFSET(INDIRECT("'"&'DATA for charts'!E$5&"'!$c70"),$R41,0)),OFFSET(INDIRECT("'"&'DATA for charts'!E$5&"'!$c70"),$R41,0),"") -> 4.619 | F41: =IF(ISNUMBER(OFFSET(INDIRECT("'"&'DATA for charts'!F$5&"'!$c70"),$R41,0)),OFFSET(INDIRECT("'"&'DATA for charts'!F$5&"'!$c70"),$R41,0),"") -> 4.5700665 | G41: =IF(ISNUMBER(OFFSET(INDIRECT("'"&'DATA for charts'!G$5&"'!$c70"),$R41,0)),OFFSET(INDIRECT("'"&'DATA for charts'!G$5&"'!$c70"),$R41,0),"") -> 4.7381 | H41: =IF(ISNUMBER(OFFSET(INDIRECT("'"&'DATA for charts'!H$5&"'!$c70"),$R41,0)),OFFSET(INDIRECT("'"&'DATA for charts'!H$5&"'!$c70"),$R41,0),"") -> 4.86989 | I41: =MIN(C41:H41) -> 4.5249314 | J41: =MAX(C41:H41) -> 4.86989 | K41: =AVERAGE(C41:H41) -> 4.6643976 | L41: =ABS((J41-I41)/K41) -> 0.073955666 | N41: =IF(ISNUMBER(YourData!$C100),YourData!$C100,"") | Q41: 22 | R41: =R40+1 -> 30
...

Sheet Tables 2
B1: ='Title Page'!$B$30 -> ASHRAE Standard 140-2023, Informative Annex B8, Section B8.1
B2: ='Title Page'!$B$32 -> Example Results for Section 7 - Building Thermal Envelope and Fabric Load Cases 195-995 & 600FF-980FF
B3: ='Title Page'!$B$34
G4: Note: The statistics in the tables below are based on the listed example results.
G5: These statistics do not have any substantial importance and are not to be interpreted as acceptance criteria.
B7: Table B8-3. Annual Hourly Integrated Peak Heating Loads
B8: Simulation Model: | C8: ='DATA for charts'!C6 -> BSIMAC | G8: ='DATA for charts'!D6 -> CSE | K8: ='DATA for charts'!E6 -> DeST | O8: ='DATA for charts'!F6 -> EnergyPlus | S8: ='DATA for charts'!G6 -> ESP-r | W8: ='DATA for charts'!H6 -> TRNSYS | AA8: Example Result Statistics | AG8: ='DATA for charts'!$S$6 -> Tested Prg
C9: ='DATA for charts'!C7 | G9: ='DATA for charts'!D7 | K9: ='DATA for charts'!E7 | O9: ='DATA for charts'!F7 | S9: ='DATA for charts'!G7 | W9: ='DATA for charts'!H7 | AA9: Min | AB9: Max | AC9: Mean | AD9: (Max-Min)/ | AG9: ='DATA for charts'!$S$7
B10: Case | C10: kW | D10: Mo. | E10: Day | F10: Hr | G10: kW | H10: Mo. | I10: Day | J10: Hr | K10: kW | L10: Mo. | M10: Day | N10: Hr | O10: kW | P10: Mo. | Q10: Day | R10: Hr | S10: kW | T10: Mo. | U10: Day | V10: Hr | W10: kW | X10: Mo. | Y10: Day | Z10: Hr | AA10: kW | AB10: kW | AC10: kW | AD10: Mean** (%) | AF10: kW | AG10: Mo. | AH10: Day | AI10: Hr
B11: 600 Base Case, South Windows | C11: =IF(ISNUMBER(OFFSET(INDIRECT("'"&'DATA for charts'!$C$5&"'!$e70"),$AM11,0)),OFFSET(INDIRECT("'"&'DATA for charts'!$C$5&"'!$e70"),$AM11,0),"") -> 3.255 | D11: =IF(ISBLANK(OFFSET(INDIRECT("'"&'DATA for charts'!$C$5&"'!$f70"),$AM11,0)),"",(OFFSET(INDIRECT("'"&'DATA for charts'!$C$5&"'!$f70"),$AM11,0))) -> Nov | E11: =IF(ISNUMBER(OFFSET(INDIRECT("'"&'DATA for charts'!$C$5&"'!$g70"),$AM11,0)),OFFSET(INDIRECT("'"&'DATA for charts'!$C$5&"'!$g70"),$AM11,0),"") -> 26 | F11: =IF(ISNUMBER(OFFSET(INDIRECT("'"&'DATA for charts'!$C$5&"'!$h70"),$AM11,0)),OFFSET(INDIRECT("'"&'DATA for charts'!$C$5&"'!$h70"),$AM11,0),"") -> 8 | G11: =IF(ISNUMBER(OFFSET(INDIRECT("'"&'DATA for charts'!$D$5&"'!$e70"),$AM11,0)),OFFSET(INDIRECT("'"&'DATA for charts'!$D$5&"'!$e70"),$AM11,0),"") -> 3.020233 | H11: =IF(ISBLANK(OFFSET(INDIRECT("'"&'DATA for charts'!$D$5&"'!$f70"),$AM11,0)),"",(OFFSET(INDIRECT("'"&'DATA for charts'!$D$5&"'!$f70"),$AM11,0))) -> Jan | I11: =IF(ISNUMBER(OFFSET(INDIRECT("'"&'DATA for charts'!$D$5&"'!$g70"),$AM11,0)),OFFSET(INDIRECT("'"&'DATA for charts'!$D$5&"'!$g70"),$AM11,0),"") -> 1 | J11: =IF(ISNUMBER(OFFSET(INDIRECT("'"&'DATA for charts'!$D$5&"'!$h70"),$AM11,0)),OFFSET(INDIRECT("'"&'DATA for charts'!$D$5&"'!$h70"),$AM11,0),"") -> 1 | K11: =IF(ISNUMBER(OFFSET(INDIRECT("'"&'DATA for charts'!$E$5&"'!$e70"),$AM11,0)),OFFSET(INDIRECT("'"&'DATA for charts'!$E$5&"'!$e70"),$AM11,0),"") -> 3.035 | L11: =IF(ISBLANK(OFFSET(INDIRECT("'"&'DATA for charts'!$E$5&"'!$f70"),$AM11,0)),"",(OFFSET(INDIRECT("'"&'DATA for charts'!$E$5&"'!$f70"),$AM11,0))) -> Jan | M11: =IF(ISNUMBER(OFFSET(INDIRECT("'"&'DATA for charts'!$E$5&"'!$g70"),$AM11,0)),OFFSET(INDIRECT("'"&'DATA for charts'!$E$5&"'!$g70"),$AM11,0),"") -> 1 | N11: =IF(ISNUMBER(OFFSET(INDIRECT("'"&'DATA for charts'!$E$5&"'!$h70"),$AM11,0)),OFFSET(INDIRECT("'"&'DATA for charts'!$E$5&"'!$h70"),$AM11,0),"") -> 0 | O11: =IF(ISNUMBER(OFFSET(INDIRECT("'"&'DATA for charts'!$F$5&"'!$e70"),$AM11,0)),OFFSET(INDIRECT("'"&'DATA for charts'!$F$5&"'!$e70"),$AM11,0),"") -> 3.2044263 | P11: =IF(ISBLANK(OFFSET(INDIRECT("'"&'DATA for charts'!$F$5&"'!$f70"),$AM11,0)),"",(OFFSET(INDIRECT("'"&'DATA for charts'!$F$5&"'!$f70"),$AM11,0))) -> Dec | Q11: =IF(ISNUMBER(OFFSET(INDIRECT("'"&'DATA for charts'!$F$5&"'!$g70"),$AM11,0)),OFFSET(INDIRECT("'"&'DATA for charts'!$F$5&"'!$g70"),$AM11,0),"") -> 31 | R11: =IF(ISNUMBER(OFFSET(INDIRECT("'"&'DATA for charts'!$F$5&"'!$h70"),$AM11,0)),OFFSET(INDIRECT("'"&'DATA for charts'!$F$5&"'!$h70"),$AM11,0),"") -> 24 | S11: =IF(ISNUMBER(OFFSET(INDIRECT("'"&'DATA for charts'!$G$5&"'!$e70"),$AM11,0)),OFFSET(INDIRECT("'"&'DATA for charts'!$G$5&"'!$e70"),$AM11,0),"") -> 3.228 | T11: =IF(ISBLANK(OFFSET(INDIRECT("'"&'DATA for charts'!$G$5&"'!$f70"),$AM11,0)),"",(OFFSET(INDIRECT("'"&'DATA for charts'!$G$5&"'!$f70"),$AM11,0))) -> Jan | U11: =IF(ISNUMBER(OFFSET(INDIRECT("'"&'DATA for charts'!$G$5&"'!$g70"),$AM11,0)),OFFSET(INDIRECT("'"&'DATA for charts'!$G$5&"'!$g70"),$AM11,0),"") -> 1 | V11: =IF(ISNUMBER(OFFSET(INDIRECT("'"&'DATA for charts'!$G$5&"'!$h70"),$AM11,0)),OFFSET(INDIRECT("'"&'DATA for charts'!$G$5&"'!$h70"),$AM11,0),"") -> 1 | W11: =IF(ISNUMBER(OFFSET(INDIRECT("'"&'DATA for charts'!$H$5&"'!$e70"),$AM11,0)),OFFSET(INDIRECT("'"&'DATA for charts'!$H$5&"'!$e70"),$AM11,0),"") -> 3.3588931 | X11: =IF(ISBLANK(OFFSET(INDIRECT("'"&'DATA for charts'!$H$5&"'!$f70"),$AM11,0)),"",(OFFSET(INDIRECT("'"&'DATA for charts'!$H$5&"'!$f70"),$AM11,0))) -> Jan | Y11: =IF(ISNUMBER(OFFSET(INDIRECT("'"&'DATA for charts'!$H$5&"'!$g70"),$AM11,0)),OFFSET(INDIRECT("'"&'DATA for charts'!$H$5&"'!$g70"),$AM11,0),"") -> 1 | Z11: =IF(ISNUMBER(OFFSET(INDIRECT("'"&'DATA for charts'!$H$5&"'!$h70"),$AM11,0)),OFFSET(INDIRECT("'"&'DATA for charts'!$H$5&"'!$h70"),$AM11,0),"") -> 1 | AA11: =MIN(C11,G11,K11,O11,S11,W11) -> 3.020233 | AB11: =MAX(C11,G11,K11,O11,S11,W11) -> 3.3588931 | AC11: =AVERAGE(C11,G11,K11,O11,S11,W11) -> 3.1835921 | AD11: =IF(AC11=0,"----",ABS((AB11-AA11)/AC11)) -> 0.10637673 | AF11: =IF(ISNUMBER(YourData!$E70),YourData!$E70,"") | AG11: =IF(ISBLANK(YourData!$F70),"",YourData!$F70) | AH11: =IF(ISNUMBER(YourData!$G70),YourData!$G70,"") | AI11: =IF(ISNUMBER(YourData!$H70),YourData!$H70,"") | AL11: 0 | AM11: 0
